{
    "registryname": "alloy_furnace_tier_4",
    "localizedname": "Ultra Alloy Smelter",
    
    "parts": [
        {
            "x": -1,
            "y": -1,
            "z": 0,
            "elements": "modularmachinery:blockcasing@4"
        },
        {
            "x": 0,
            "y": -1,
            "z": 0,
            "elements": "modularmachinery:blockcasing@2"
        },
        {
            "x": 1,
            "y": -1,
            "z": 0,
            "elements": "modularmachinery:blockcasing@0"
        },
        {
            "x": 2,
            "y": -1,
            "z": 0,
            "elements": "modularmachinery:blockcasing@2"
        },
        {
            "x": 3,
            "y": -1,
            "z": 0,
            "elements": "modularmachinery:blockcasing@4"
        },		
        {
            "x": -1,
            "y": -1,
            "z": 1,
            "elements": "modularmachinery:blockcasing@2"
        },
        {
            "x": 0,
            "y": -1,
            "z": 1,
            "elements": "modularmachinery:blockcasing@0"
        },
        {
            "x": 1,
            "y": -1,
            "z": 1,
            "elements": "modularmachinery:blockcasing@0"
        },
        {
            "x": 2,
            "y": -1,
            "z": 1,
            "elements": "modularmachinery:blockcasing@0"
        },
        {
            "x": 3,
            "y": -1,
            "z": 1,
            "elements": "modularmachinery:blockcasing@2"
        },
        {
            "x": -1,
            "y": -1,
            "z": 2,
            "elements": "modularmachinery:blockcasing@0"
        },
        {
            "x": 0,
            "y": -1,
            "z": 2,
            "elements": "modularmachinery:blockcasing@0"
        },
        {
            "x": 1,
            "y": -1,
            "z": 2,
            "elements": "modularmachinery:blockcasing@0"
        },
        {
            "x": 2,
            "y": -1,
            "z": 2,
            "elements": "modularmachinery:blockcasing@0"
        },
        {
            "x": 3,
            "y": -1,
            "z": 2,
            "elements": "modularmachinery:blockcasing@0"
        },
        {
            "x": -1,
            "y": -1,
            "z": 3,
            "elements": "modularmachinery:blockcasing@2"
        },
        {
            "x": 0,
            "y": -1,
            "z": 3,
            "elements": "modularmachinery:blockcasing@0"
        },
        {
            "x": 1,
            "y": -1,
            "z": 3,
            "elements": "modularmachinery:blockcasing@0"
        },
        {
            "x": 2,
            "y": -1,
            "z": 3,
            "elements": "modularmachinery:blockcasing@0"
        },
        {
            "x": 3,
            "y": -1,
            "z": 3,
            "elements": "modularmachinery:blockcasing@2"
        },
        {
            "x": -1,
            "y": -1,
            "z": 4,
            "elements": "modularmachinery:blockcasing@4"
        },
        {
            "x": 0,
            "y": -1,
            "z": 4,
            "elements": "modularmachinery:blockcasing@2"
        },
        {
            "x": 1,
            "y": -1,
            "z": 4,
            "elements": "modularmachinery:blockcasing@0"
        },
        {
            "x": 2,
            "y": -1,
            "z": 4,
            "elements": "modularmachinery:blockcasing@2"
        },
        {
            "x": 3,
            "y": -1,
            "z": 4,
            "elements": "modularmachinery:blockcasing@4"
        },
		
        {
            "x": -1,
            "y": 0,
            "z": 0,
            "elements": "modularmachinery:blockcasing@4"
        },
        {
            "x": 1,
            "y": 0,
            "z": 0,
            "elements": "modularmachinery:blockcasing@5"
        },
        {
            "x": 2,
            "y": 0,
            "z": 0,
            "elements": "casings_2"
        },
        {
            "x": 3,
            "y": 0,
            "z": 0,
            "elements": "modularmachinery:blockcasing@4"
        },
        {
            "x": -1,
            "y": 0,
            "z": 1,
            "elements": "advancedrocketry:metal0@0"
        },
        {
            "x": 0,
            "y": 0,
            "z": 1,
            "elements": "enderio:block_fluid_fire_water@0"
        },
        {
            "x": 1,
            "y": 0,
            "z": 1,
            "elements": "enderio:block_fluid_fire_water@0"
        },
        {
            "x": 2,
            "y": 0,
            "z": 1,
            "elements": "enderio:block_fluid_fire_water@0"
        },
        {
            "x": 3,
            "y": 0,
            "z": 1,
            "elements": "advancedrocketry:metal0@0"
        },

        {
            "x": -1,
            "y": 0,
            "z": 2,
            "elements": [
                "casings_2"
            ]
        },
        {
            "x": 0,
            "y": 0,
            "z": 2,
            "elements": "enderio:block_fluid_fire_water@0"
        },
        {
            "x": 1,
            "y": 0,
            "z": 2,
            "elements": "enderio:block_alloy_endergy@3"
        },
        {
            "x": 2,
            "y": 0,
            "z": 2,
            "elements": "enderio:block_fluid_fire_water@0"
        },
        {
            "x": 3,
            "y": 0,
            "z": 2,
            "elements": [
                "casings_2"
            ]
        },
        {
            "x": -1,
            "y": 0,
            "z": 3,
            "elements": "advancedrocketry:metal0@0"
        },
        {
            "x": 0,
            "y": 0,
            "z": 3,
            "elements": "enderio:block_fluid_fire_water@0"
        },
        {
            "x": 1,
            "y": 0,
            "z": 3,
            "elements": "enderio:block_fluid_fire_water@0"
        },
        {
            "x": 2,
            "y": 0,
            "z": 3,
            "elements": "enderio:block_fluid_fire_water@0"
        },
        {
            "x": 3,
            "y": 0,
            "z": 3,
            "elements": "advancedrocketry:metal0@0"
        },
        {
            "x": -1,
            "y": 0,
            "z": 4,
            "elements": "modularmachinery:blockcasing@4"
        },
        {
            "x": 0,
            "y": 0,
            "z": 4,
            "elements": "advancedrocketry:metal0@0"
        },
        {
            "x": 1,
            "y": 0,
            "z": 4,
            "elements": "casings_2"
        },
        {
            "x": 2,
            "y": 0,
            "z": 4,
            "elements": "advancedrocketry:metal0@0"
        },
        {
            "x": 3,
            "y": 0,
            "z": 4,
            "elements": "modularmachinery:blockcasing@4"
        },

        {
            "x": -1,
            "y": 1,
            "z": 0,
            "elements": "modularmachinery:blockcasing@4"
        },
        {
            "x": 0,
            "y": 1,
            "z": 0,
            "elements": "modularmachinery:blockcasing@2"
        },
        {
            "x": 1,
            "y": 1,
            "z": 0,
            "elements": "modularmachinery:blockcasing@0"
        },
        {
            "x": 2,
            "y": 1,
            "z": 0,
            "elements": "modularmachinery:blockcasing@2"
        },
        {
            "x": 3,
            "y": 1,
            "z": 0,
            "elements": "modularmachinery:blockcasing@4"
        },
        {
            "x": -1,
            "y": 1,
            "z": 1,
            "elements": "modularmachinery:blockcasing@2"
        },
        {
            "x": 0,
            "y": 1,
            "z": 1,
            "elements": "modularmachinery:blockcasing@1"
        },
        {
            "x": 1,
            "y": 1,
            "z": 1,
            "elements": "modularmachinery:blockcasing@1"
        },
        {
            "x": 2,
            "y": 1,
            "z": 1,
            "elements": "modularmachinery:blockcasing@1"
        },
        {
            "x": 3,
            "y": 1,
            "z": 1,
            "elements": "modularmachinery:blockcasing@2"
        },
        {
            "x": -1,
            "y": 1,
            "z": 2,
            "elements": "modularmachinery:blockcasing@0"
        },
        {
            "x": 0,
            "y": 1,
            "z": 2,
            "elements": "modularmachinery:blockcasing@1"
        },
        {
            "x": 1,
            "y": 1,
            "z": 2,
            "elements": "modularmachinery:blockcasing@0"
        },
        {
            "x": 2,
            "y": 1,
            "z": 2,
            "elements": "modularmachinery:blockcasing@1"
        },
        {
            "x": 3,
            "y": 1,
            "z": 2,
            "elements": "modularmachinery:blockcasing@0"
        },
        {
            "x": -1,
            "y": 1,
            "z": 3,
            "elements": "modularmachinery:blockcasing@2"
        },
        {
            "x": 0,
            "y": 1,
            "z": 3,
            "elements": "modularmachinery:blockcasing@1"
        },
        {
            "x": 1,
            "y": 1,
            "z": 3,
            "elements": "modularmachinery:blockcasing@1"
        },
        {
            "x": 2,
            "y": 1,
            "z": 3,
            "elements": "modularmachinery:blockcasing@1"
        },
        {
            "x": 3,
            "y": 1,
            "z": 3,
            "elements": "modularmachinery:blockcasing@2"
        },
        {
            "x": -1,
            "y": 1,
            "z": 4,
            "elements": "modularmachinery:blockcasing@4"
        },
        {
            "x": 0,
            "y": 1,
            "z": 4,
            "elements": "modularmachinery:blockcasing@2"
        },
        {
            "x": 1,
            "y": 1,
            "z": 4,
            "elements": "modularmachinery:blockcasing@0"
        },
        {
            "x": 2,
            "y": 1,
            "z": 4,
            "elements": "modularmachinery:blockcasing@2"
        },
        {
            "x": 3,
            "y": 1,
            "z": 4,
            "elements": "modularmachinery:blockcasing@4"
        }
    ]
}