{
    "registryname": "cryogenicairdistillation",
    "localizedname": "Cryogenic Air Distillation",
	"color": "4fbaef",
    "parts": [
	
	
		{
            "x": 0,
            "y": 11,
            "z": 3,
            "elements": "ore:blockIron"
        },
        {
            "x": 0,
            "y": 11,
            "z": 2,
            "elements": "ore:blockIron"
        },
		{
            "x": -1,
            "y": 11,
            "z": 3,
            "elements": "ore:blockIron"
        },
        {
            "x": -1,
            "y": 11,
            "z": 2,
            "elements": "ore:blockIron"
        },
	
	
	
		{
            "x": 0,
            "y": 10,
            "z": 4,
            "elements": "ore:blockIron"
        },
        {
            "x": 0,
            "y": 10,
            "z": 1,
            "elements": "ore:blockIron"
        },
		{
            "x": 1,
            "y": 10,
            "z": 3,
            "elements": "ore:blockIron"
        },
        {
            "x": 1,
            "y": 10,
            "z": 2,
            "elements": "ore:blockIron"
        },
		{
            "x": -1,
            "y": 10,
            "z": 4,
            "elements": "ore:blockIron"
        },
        {
            "x": -1,
            "y": 10,
            "z": 1,
            "elements": "ore:blockIron"
        },
		{
            "x": -2,
            "y": 10,
            "z": 3,
            "elements": "ore:blockIron"
        },
        {
            "x": -2,
            "y": 10,
            "z": 2,
            "elements": "ore:blockIron"
        },
	
	{
            "x": 0,
            "y": 9,
            "z": 4,
            "elements": "ore:blockIron"
        },
        {
            "x": 0,
            "y": 9,
            "z": 1,
            "elements": "ore:blockIron"
        },
		{
            "x": 1,
            "y": 9,
            "z": 3,
            "elements": "ore:blockIron"
        },
        {
            "x": 1,
            "y": 9,
            "z": 2,
            "elements": "ore:blockIron"
        },
		{
            "x": -1,
            "y": 9,
            "z": 4,
            "elements": "ore:blockIron"
        },
        {
            "x": -1,
            "y": 9,
            "z": 1,
            "elements": "ore:blockIron"
        },
		{
            "x": -2,
            "y": 9,
            "z": 3,
            "elements": "ore:blockIron"
        },
        {
            "x": -2,
            "y": 9,
            "z": 2,
            "elements": "ore:blockIron"
        },
	
	
	{
            "x": 0,
            "y": 8,
            "z": 4,
            "elements": "ore:blockIron"
        },
        {
            "x": 0,
            "y": 8,
            "z": 1,
            "elements": "ore:blockIron"
        },
		{
            "x": 1,
            "y": 8,
            "z": 3,
            "elements": "ore:blockIron"
        },
        {
            "x": 1,
            "y": 8,
            "z": 2,
            "elements": "ore:blockIron"
        },
		{
            "x": -1,
            "y": 8,
            "z": 4,
            "elements": "ore:blockIron"
        },
        {
            "x": -1,
            "y": 8,
            "z": 1,
            "elements": "ore:blockIron"
        },
		{
            "x": -2,
            "y": 8,
            "z": 3,
            "elements": "ore:blockIron"
        },
        {
            "x": -2,
            "y": 8,
            "z": 2,
            "elements": "ore:blockIron"
        },
	
	
	{
            "x": 0,
            "y": 7,
            "z": 4,
            "elements": "ore:blockIron"
        },
        {
            "x": 0,
            "y": 7,
            "z": 1,
            "elements": "ore:blockIron"
        },
		{
            "x": 1,
            "y": 7,
            "z": 3,
            "elements": "ore:blockIron"
        },
        {
            "x": 1,
            "y": 7,
            "z": 2,
            "elements": "ore:blockIron"
        },
		{
            "x": -1,
            "y": 7,
            "z": 4,
            "elements": "ore:blockIron"
        },
        {
            "x": -1,
            "y": 7,
            "z": 1,
            "elements": "ore:blockIron"
        },
		{
            "x": -2,
            "y": 7,
            "z": 3,
            "elements": "ore:blockIron"
        },
        {
            "x": -2,
            "y": 7,
            "z": 2,
            "elements": "ore:blockIron"
        },
	
	
	{
            "x": 0,
            "y": 6,
            "z": 4,
            "elements": "ore:blockIron"
        },
        {
            "x": 0,
            "y": 6,
            "z": 1,
            "elements": "ore:blockIron"
        },
		{
            "x": 1,
            "y": 6,
            "z": 3,
            "elements": "ore:blockIron"
        },
        {
            "x": 1,
            "y": 6,
            "z": 2,
            "elements": "ore:blockIron"
        },
		{
            "x": -1,
            "y": 6,
            "z": 4,
            "elements": "ore:blockIron"
        },
        {
            "x": -1,
            "y": 6,
            "z": 1,
            "elements": "ore:blockIron4"
        },
		{
            "x": -2,
            "y": 6,
            "z": 3,
            "elements": "ore:blockIron"
        },
        {
            "x": -2,
            "y": 6,
            "z": 2,
            "elements": "ore:blockIron"
        },
	
	
	{
            "x": 0,
            "y": 5,
            "z": 4,
            "elements": "ore:blockIron"
        },
        {
            "x": 0,
            "y": 5,
            "z": 1,
            "elements": "ore:blockIron"
        },
		{
            "x": 1,
            "y": 5,
            "z": 3,
            "elements": "ore:blockIron"
        },
        {
            "x": 1,
            "y": 5,
            "z": 2,
            "elements": "ore:blockIron"
        },
		{
            "x": -1,
            "y": 5,
            "z": 4,
            "elements": "ore:blockIron"
        },
        {
            "x": -1,
            "y": 5,
            "z": 1,
            "elements": "ore:blockIron"
        },
		{
            "x": -2,
            "y": 5,
            "z": 3,
            "elements": "ore:blockIron4"
        },
        {
            "x": -2,
            "y": 5,
            "z": 2,
            "elements": "ore:blockIron"
        },
	
	
	{
            "x": 0,
            "y": 4,
            "z": 4,
            "elements": "ore:blockIron"
        },
        {
            "x": 0,
            "y": 4,
            "z": 1,
            "elements": "ore:blockIron"
        },
		{
            "x": 1,
            "y": 4,
            "z": 3,
            "elements": "ore:blockIron"
        },
        {
            "x": 1,
            "y": 4,
            "z": 2,
            "elements": "ore:blockIron"
        },
		{
            "x": -1,
            "y": 4,
            "z": 4,
            "elements": "gregtech:metal_casing@4"
        },
        {
            "x": -1,
            "y": 4,
            "z": 1,
            "elements": "ore:blockIron"
        },
		{
            "x": -2,
            "y": 4,
            "z": 3,
            "elements": "ore:blockIron"
        },
        {
            "x": -2,
            "y": 4,
            "z": 2,
            "elements": "ore:blockIron"
        },
	
	
	
		{
            "x": 0,
            "y": 3,
            "z": 4,
            "elements": "ore:blockIron"
        },
        {
            "x": 0,
            "y": 3,
            "z": 1,
            "elements": "ore:blockIron"
        },
		{
            "x": 1,
            "y": 3,
            "z": 3,
            "elements": "ore:blockIron"
        },
        {
            "x": 1,
            "y": 3,
            "z": 2,
            "elements": "ore:blockIron"
        },
		{
            "x": -1,
            "y": 3,
            "z": 4,
            "elements": "ore:blockIron"
        },
        {
            "x": -1,
            "y": 3,
            "z": 1,
            "elements": "ore:blockIron"
        },
		{
            "x": -2,
            "y": 3,
            "z": 3,
            "elements": "ore:blockIron"
        },
        {
            "x": -2,
            "y": 3,
            "z": 2,
            "elements": "ore:blockIron"
        },
	
	
	
	
	
		{
            "x": 0,
            "y": 2,
            "z": 4,
            "elements": "ore:blockIron"
        },
        {
            "x": 0,
            "y": 2,
            "z": 1,
            "elements": "ore:blockIron"
        },
		{
            "x": 1,
            "y": 2,
            "z": 3,
            "elements": "ore:blockIron"
        },
        {
            "x": 1,
            "y": 2,
            "z": 2,
            "elements": "ore:blockIron"
        },
		{
            "x": -1,
            "y": 2,
            "z": 4,
            "elements": "ore:blockIron"
        },
        {
            "x": -1,
            "y": 2,
            "z": 1,
            "elements": "ore:blockIron"
        },
		{
            "x": -2,
            "y": 2,
            "z": 3,
            "elements": "ore:blockIron"
        },
        {
            "x": -2,
            "y": 2,
            "z": 2,
            "elements": "ore:blockIron"
        },
	
	
	
	
		{
            "x": 0,
            "y": 1,
            "z": 5,
            "elements": "ore:blockIron"
        },
		{
            "x": 0,
            "y": 1,
            "z": 4,
            "elements": "ore:blockIron"
        },
        {
            "x": 0,
            "y": 1,
            "z": 1,
            "elements": "ore:blockIron"
        },
		{
            "x": 0,
            "y": 1,
            "z": 0,
            "elements": "ore:blockIron"
        },
		{
            "x": 1,
            "y": 1,
            "z": 5,
            "elements": "ore:blockIron"
        },
		{
            "x": 1,
            "y": 1,
            "z": 4,
            "elements": "ore:blockIron"
        },
		{
            "x": 1,
            "y": 1,
            "z": 3,
            "elements": "ore:blockIron"
        },
        {
            "x": 1,
            "y": 1,
            "z": 2,
            "elements": "ore:blockIron"
        },
        {
            "x": 1,
            "y": 1,
            "z": 1,
            "elements": "ore:blockIron"
        },
        {
            "x": 1,
            "y": 1,
            "z": 0,
            "elements": "ore:blockIron"
        },
		{
            "x": 2,
            "y": 1,
            "z": 5,
            "elements": "ore:blockIron"
        },
		{
            "x": 2,
            "y": 1,
            "z": 4,
            "elements": "ore:blockIron"
        },
		{
            "x": 2,
            "y": 1,
            "z": 3,
            "elements": "ore:blockGold"
        },
        {
            "x": 2,
            "y": 1,
            "z": 2,
            "elements": "ore:blockGold"
        },
        {
            "x": 2,
            "y": 1,
            "z": 1,
            "elements": "ore:blockGold"
        },
		{
            "x": -1,
            "y": 1,
            "z": 5,
            "elements": "ore:blockGold"
        },
		{
            "x": -1,
            "y": 1,
            "z": 4,
            "elements": "ore:blockIron"
        },
        {
            "x": -1,
            "y": 1,
            "z": 1,
            "elements": "ore:blockIron"
        },
        {
            "x": -1,
            "y": 1,
            "z": 0,
            "elements": "ore:blockGold"
        },
		{
            "x": -2,
            "y": 1,
            "z": 5,
            "elements": "ore:blockGold"
        },
		{
            "x": -2,
            "y": 1,
            "z": 4,
            "elements": "ore:blockGold"
        },
		{
            "x": -2,
            "y": 1,
            "z": 3,
            "elements": "ore:blockIron"
        },
        {
            "x": -2,
            "y": 1,
            "z": 2,
            "elements": "ore:blockIron"
        },
        {
            "x": -2,
            "y": 1,
            "z": 1,
            "elements": "ore:blockGold"
        },
        {
            "x": -2,
            "y": 1,
            "z": 0,
            "elements": "ore:blockGold"
        },
		{
            "x": -3,
            "y": 1,
            "z": 5,
            "elements": "ore:blockGold"
        },
		{
            "x": -3,
            "y": 1,
            "z": 4,
            "elements": "ore:blockGold"
        },
		{
            "x": -3,
            "y": 1,
            "z": 3,
            "elements": "ore:blockGold"
        },
        {
            "x": -3,
            "y": 1,
            "z": 2,
            "elements": "ore:blockGold"
        },
        {
            "x": -3,
            "y": 1,
            "z": 1,
            "elements": "ore:blockGold"
        },
		{
            "x": -3,
            "y": 1,
            "z": 0,
            "elements": "ore:blockGold"
        },
		{
            "x": 2,
            "y": 1,
            "z": 0,
            "elements": "ore:blockGold"
        },

		
		

		{
            "x": 0,
            "y": 0,
            "z": 5,
            "elements": "modularmachinery:blockenergyinputhatch"
        },
		{
            "x": 0,
            "y": 0,
            "z": 4,
            "elements": "ore:blockGold"
        },
		{
            "x": 0,
            "y": 0,
            "z": 3,
            "elements": "ore:blockGold"
        },
        {
            "x": 0,
            "y": 0,
            "z": 2,
            "elements": "ore:blockGold"
        },
        {
            "x": 0,
            "y": 0,
            "z": 1,
            "elements": "ore:blockGold"
        },
		{
            "x": 1,
            "y": 0,
            "z": 5,
            "elements": "modularmachinery:blockfluidoutputhatch"
        },
		{
            "x": 1,
            "y": 0,
            "z": 4,
            "elements": "ore:blockGold"
        },
		{
            "x": 1,
            "y": 0,
            "z": 3,
            "elements": "ore:blockGold"
        },
        {
            "x": 1,
            "y": 0,
            "z": 2,
            "elements": "ore:blockGold"
        },
        {
            "x": 1,
            "y": 0,
            "z": 1,
            "elements": "ore:blockGold"
        },
        {
            "x": 1,
            "y": 0,
            "z": 0,
            "elements": "ore:blockGold"
        },
		{
            "x": 2,
            "y": 0,
            "z": 5,
            "elements": "modularmachinery:blockfluidoutputhatch"
        },
		{
            "x": 2,
            "y": 0,
            "z": 4,
            "elements": "ore:blockGold"
        },
		{
            "x": 2,
            "y": 0,
            "z": 3,
            "elements": "ore:blockGold"
        },
        {
            "x": 2,
            "y": 0,
            "z": 2,
            "elements": "ore:blockGold"
        },
        {
            "x": 2,
            "y": 0,
            "z": 1,
            "elements": "ore:blockGold"
        },
        {
            "x": 2,
            "y": 0,
            "z": 0,
            "elements": "ore:blockGold"
        },
		{
            "x": -1,
            "y": 0,
            "z": 5,
            "elements": "modularmachinery:blockfluidoutputhatch"
        },
		{
            "x": -1,
            "y": 0,
            "z": 4,
            "elements": "ore:blockGold"
        },
		{
            "x": -1,
            "y": 0,
            "z": 3,
            "elements": "ore:blockGold"
        },
        {
            "x": -1,
            "y": 0,
            "z": 2,
            "elements": "ore:blockGold"
        },
        {
            "x": -1,
            "y": 0,
            "z": 1,
            "elements": "ore:blockGold"
        },
        {
            "x": -1,
            "y": 0,
            "z": 0,
            "elements": "modularmachinery:blockfluidinputhatch"
        },
		{
            "x": -2,
            "y": 0,
            "z": 5,
            "elements": "modularmachinery:blockfluidoutputhatch"
        },
		{
            "x": -2,
            "y": 0,
            "z": 4,
            "elements": "ore:blockGold"
        },
		{
            "x": -2,
            "y": 0,
            "z": 3,
            "elements": "ore:blockGold"
        },
        {
            "x": -2,
            "y": 0,
            "z": 2,
            "elements": "ore:blockGold"
        },
        {
            "x": -2,
            "y": 0,
            "z": 1,
            "elements": "ore:blockGold"
        },
        {
            "x": -2,
            "y": 0,
            "z": 0,
            "elements": "ore:blockGold"
        },
		{
            "x": -3,
            "y": 0,
            "z": 5,
            "elements": "modularmachinery:blockfluidoutputhatch"
        },
		{
            "x": -3,
            "y": 0,
            "z": 4,
            "elements": "ore:blockGold"
        },
		{
            "x": -3,
            "y": 0,
            "z": 3,
            "elements": "ore:blockGold"
        },
        {
            "x": -3,
            "y": 0,
            "z": 2,
            "elements": "ore:blockGold"
        },
        {
            "x": -3,
            "y": 0,
            "z": 1,
            "elements": "ore:blockGold"
        },
        {
            "x": -3,
            "y": 0,
            "z": 0,
            "elements": "ore:blockGold"
        }

    ]
}