{
    "registryname": "oil_refinery",
    "localizedname": "Oil Refinery",
    "color": "ad0519",
	"modifiers": [
        {
            "elements": "minecraft:concrete_powder@6",
            "x": 0,
            "y": -1,
            "z": 0,
            "description": "+20% speed, +50% RF/t",
            "modifier": [{
                "io": "output",
                "target": "duration",
                "operation": 1,
                "multiplier": 0.8
            },
		    {
				"io": "input",
				"target": "energy",
				"operation": 1,
				"multiplier": 1.5
			}]
        },
		{
            "elements": "minecraft:concrete_powder@7",
            "x": 0,
            "y": -1,
            "z": 0,
            "description": "+30% speed, +60% RF/t",
            "modifier": [{
                "io": "output",
                "target": "duration",
                "operation": 1,
                "multiplier": 0.7
            },
		    {
				"io": "input",
				"target": "energy",
				"operation": 1,
				"multiplier": 1.6
			}]
        },
		{
            "elements": "minecraft:concrete_powder@8",
            "x": 0,
            "y": -1,
            "z": 0,
            "description": "+50% speed, +70% RF/t",
            "modifier": [{
                "io": "output",
                "target": "duration",
                "operation": 1,
                "multiplier": 0.5
            },
		    {
				"io": "input",
				"target": "energy",
				"operation": 1,
				"multiplier": 1.7
			}]
        },
        {
            "elements": "minecraft:concrete_powder@0",
            "x": 1,
            "y": -1,
            "z": 0,
            "description": "+4% productivity, +40% RF/t, -15% speed",
            "modifier": [{
                "io": "input",
                "target": "item",
                "operation": 0,
                "multiplier": -0.04,
                "affectChance": true
            },
			{
                "io": "output",
                "target": "duration",
                "operation": 1,
                "multiplier": 1.15
            },
		    {
				"io": "input",
				"target": "energy",
				"operation": 1,
				"multiplier": 1.4
			}]
        },
		{
            "elements": "minecraft:concrete_powder@1",
            "x": 1,
            "y": -1,
            "z": 0,
            "description": "+6% productivity, +60% RF/t, -15% speed",
            "modifier": [{
                "io": "input",
                "target": "item",
                "operation": 0,
                "multiplier": -0.06,
                "affectChance": true
            },
			{
                "io": "output",
                "target": "duration",
                "operation": 1,
                "multiplier": 1.15
            },
		    {
				"io": "input",
				"target": "energy",
				"operation": 1,
				"multiplier": 1.6
			}]
        },
		{
            "elements": "minecraft:concrete_powder@2",
            "x": 1,
            "y": -1,
            "z": 0,
            "description": "+10% productivity, +80% RF/t, -15% speed",
            "modifier": [{
                "io": "input",
                "target": "item",
                "operation": 0,
                "multiplier": -0.10,
                "affectChance": true
            },
			{
                "io": "output",
                "target": "duration",
                "operation": 1,
                "multiplier": 1.15
            },
		    {
				"io": "input",
				"target": "energy",
				"operation": 1,
				"multiplier": 1.8
			}]
        },
		{
            "elements": "minecraft:concrete_powder@3",
            "x": 0,
            "y": 1,
            "z": 0,
            "description": "-30% RF/t",
            "modifier": [{
                "io": "input",
                "target": "energy",
                "operation": 1,
                "multiplier": 0.7
            }]
        },
		{
            "elements": "minecraft:concrete_powder@4",
            "x": 0,
            "y": 1,
            "z": 0,
            "description": "-40% RF/t",
            "modifier": [{
                "io": "input",
                "target": "energy",
                "operation": 1,
                "multiplier": 0.6
            }]
        },
		{
            "elements": "minecraft:concrete_powder@5",
            "x": 0,
            "y": 1,
            "z": 0,
            "description": "-50% RF/t",
            "modifier": [{
                "io": "input",
                "target": "energy",
                "operation": 1,
                "multiplier": 0.5
            }]
        }

    ],
    "parts": [
        {
            "x": -1,
            "y": 2,
            "z": 3,
            "elements": [
                "immersiveengineering:sheetmetal@9"
            ]
        },
        {
            "x": -1,
            "y": 0,
            "z": 0,
            "elements": [
                "immersiveengineering:sheetmetal@9"
            ]
        },
        {
            "x": 2,
            "y": 2,
            "z": 1,
            "elements": [
                "immersiveengineering:sheetmetal@9"
            ]
        },
        {
            "x": 1,
            "y": 0,
            "z": 0,
            "elements": [
                "immersiveengineering:sheetmetal@9"
            ]
        },
        {
            "x": 2,
            "y": 0,
            "z": 0,
            "elements": [
                "immersiveengineering:sheetmetal@9"
            ]
        },
        {
            "x": 2,
            "y": 2,
            "z": 3,
            "elements": [
                "immersiveengineering:sheetmetal@9"
            ]
        },
        {
            "x": 1,
            "y": 0,
            "z": 2,
            "elements": [
                "immersiveengineering:metal_device1@6"
            ]
        },
        {
            "x": 1,
            "y": 7,
            "z": 1,
            "elements": [
                "modularmachinery:blockcasing@1"
            ]
        },
        {
            "x": 0,
            "y": 5,
            "z": 0,
            "elements": [
                "immersiveengineering:metal_decoration1_slab@1",
		"immersiveengineering:metal_decoration1_slab@2",
		"immersiveengineering:metal_decoration1_slab@3"
            ]
        },
        {
            "x": 2,
            "y": 7,
            "z": 1,
            "elements": [
                "modularmachinery:blockcasing@1"
            ]
        },
        {
            "x": 1,
            "y": 5,
            "z": 0,
            "elements": [
                "immersiveengineering:sheetmetal@9"
            ]
        },
        {
            "x": 2,
            "y": -1,
            "z": 0,
            "elements": [
                "modularmachinery:blockfluidinputhatch@3"
            ]
        },
        {
            "x": 0,
            "y": 5,
            "z": 2,
            "elements": [
                "immersiveengineering:metal_decoration1_slab@1",
		"immersiveengineering:metal_decoration1_slab@2",
		"immersiveengineering:metal_decoration1_slab@3"
            ]
        },
        {
            "x": 2,
            "y": 5,
            "z": 0,
            "elements": [
                "immersiveengineering:sheetmetal@9"
            ]
        },
        {
            "x": 1,
            "y": -1,
            "z": 0,
            "elements": [
                "immersiveengineering:metal_decoration0@5"
            ]
        },
        {
            "x": 0,
            "y": -1,
            "z": 0,
            "elements": [
	        "immersiveengineering:metal_decoration1@1",
                "immersiveengineering:metal_decoration1@2",
		"immersiveengineering:metal_decoration1@3"
            ]
        },
        {
            "x": -1,
            "y": 1,
            "z": 0,
            "elements": [
                "immersiveengineering:sheetmetal@9"
            ]
        },
        {
            "x": 1,
            "y": 5,
            "z": 2,
            "elements": [
                "immersiveengineering:metal_device1@6"
            ]
        },
        {
            "x": 0,
            "y": 3,
            "z": 1,
            "elements": [
                "immersiveengineering:metal_decoration1@1",
                "immersiveengineering:metal_decoration1@2",
				"immersiveengineering:metal_decoration1@3"
            ]
        },
        {
            "x": 3,
            "y": 5,
            "z": 0,
            "elements": [
                "immersiveengineering:metal_decoration1_slab@1",
		"immersiveengineering:metal_decoration1_slab@2",
		"immersiveengineering:metal_decoration1_slab@3"
            ]
        },
        {
            "x": 2,
            "y": 5,
            "z": 2,
            "elements": [
                "immersiveengineering:metal_decoration1_slab@1",
		"immersiveengineering:metal_decoration1_slab@2",
		"immersiveengineering:metal_decoration1_slab@3"
            ]
        },
        {
            "x": -1,
            "y": -1,
            "z": 0,
            "elements": [
                "modularmachinery:blockfluidoutputhatch@2"
            ]
        },
        {
            "x": 3,
            "y": 5,
            "z": 2,
            "elements": [
                "immersiveengineering:metal_decoration1_slab@1",
				"immersiveengineering:metal_decoration1_slab@2",
				"immersiveengineering:metal_decoration1_slab@3"
            ]
        },
        {
            "x": 2,
            "y": 3,
            "z": 1,
            "elements": [
                "immersiveengineering:sheetmetal@9"
            ]
        },
        {
            "x": 1,
            "y": 1,
            "z": 0,
            "elements": [
                "immersiveengineering:sheetmetal@9"
            ]
        },
        {
            "x": 2,
            "y": 1,
            "z": 0,
            "elements": [
                "immersiveengineering:sheetmetal@9"
            ]
        },
        {
            "x": -1,
            "y": -1,
            "z": 1,
            "elements": [
			    "immersiveengineering:metal_decoration1@1",
                "immersiveengineering:metal_decoration1@2",
				"immersiveengineering:metal_decoration1@3"
            ]
        },
        {
            "x": 0,
            "y": -1,
            "z": 1,
            "elements": [
                "immersiveengineering:metal_decoration0@5"
            ]
        },
        {
            "x": 1,
            "y": 1,
            "z": 2,
            "elements": [
                "immersiveengineering:metal_device1@6"
            ]
        },
        {
            "x": 3,
            "y": 5,
            "z": -1,
            "elements": [
                "immersiveengineering:metal_decoration1_slab@1",
				"immersiveengineering:metal_decoration1_slab@2",
				"immersiveengineering:metal_decoration1_slab@3"
            ]
        },
        {
            "x": 2,
            "y": 5,
            "z": -1,
            "elements": [
                "immersiveengineering:metal_decoration1_slab@1",
				"immersiveengineering:metal_decoration1_slab@2",
				"immersiveengineering:metal_decoration1_slab@3"
            ]
        },
        {
            "x": 1,
            "y": -1,
            "z": 1,
            "elements": [
                "immersiveengineering:metal_decoration0@5"
            ]
        },
        {
            "x": -1,
            "y": -1,
            "z": 3,
            "elements": [
                "modularmachinery:blockfluidoutputhatch@2"
            ]
        },
        {
            "x": 0,
            "y": -1,
            "z": 3,
            "elements": [
			    "immersiveengineering:metal_decoration1@1",
                "immersiveengineering:metal_decoration1@2",
				"immersiveengineering:metal_decoration1@3"
            ]
        },
        {
            "x": 1,
            "y": 5,
            "z": -1,
            "elements": [
                "immersiveengineering:metal_decoration1_slab@1",
				"immersiveengineering:metal_decoration1_slab@2",
				"immersiveengineering:metal_decoration1_slab@3"
            ]
        },
        {
            "x": 2,
            "y": -1,
            "z": 1,
            "elements": [
                "modularmachinery:blockenergyinputhatch@2"
            ]
        },
        {
            "x": 0,
            "y": 5,
            "z": -1,
            "elements": [
                "immersiveengineering:metal_decoration1_slab@1",
				"immersiveengineering:metal_decoration1_slab@2",
				"immersiveengineering:metal_decoration1_slab@3"
            ]
        },
        {
            "x": 1,
            "y": -1,
            "z": 3,
            "elements": [
			    "immersiveengineering:metal_decoration1@1",
                "immersiveengineering:metal_decoration1@2",
				"immersiveengineering:metal_decoration1@3"
            ]
        },
        {
            "x": 2,
            "y": -1,
            "z": 3,
            "elements": [
                "modularmachinery:blockfluidoutputhatch@2"
            ]
        },
        {
            "x": 1,
            "y": 6,
            "z": 0,
            "elements": [
                "immersiveengineering:sheetmetal@9"
            ]
        },
        {
            "x": 2,
            "y": 6,
            "z": 0,
            "elements": [
                "immersiveengineering:sheetmetal@9"
            ]
        },
        {
            "x": -1,
            "y": 2,
            "z": 0,
            "elements": [
                "immersiveengineering:sheetmetal@9"
            ]
        },
        {
            "x": 1,
            "y": 6,
            "z": 2,
            "elements": [
                "immersiveengineering:metal_device1@6"
            ]
        },
        {
            "x": 0,
            "y": 4,
            "z": 1,
            "elements": [
			    "immersiveengineering:metal_decoration1@1",
                "immersiveengineering:metal_decoration1@2",
				"immersiveengineering:metal_decoration1@3"
            ]
        },
        {
            "x": 2,
            "y": 4,
            "z": 1,
            "elements": [
                "immersiveengineering:sheetmetal@9"
            ]
        },
        {
            "x": 1,
            "y": 2,
            "z": 0,
            "elements": [
                "immersiveengineering:sheetmetal@9"
            ]
        },
        {
            "x": 2,
            "y": 2,
            "z": 0,
            "elements": [
                "immersiveengineering:sheetmetal@9"
            ]
        },
        {
            "x": 0,
            "y": 0,
            "z": 1,
            "elements": [
			    "immersiveengineering:metal_decoration1@1",
                "immersiveengineering:metal_decoration1@2",
				"immersiveengineering:metal_decoration1@3"
            ]
        },
        {
            "x": 1,
            "y": 2,
            "z": 2,
            "elements": [
                "immersiveengineering:metal_device1@6"
            ]
        },
        {
            "x": -1,
            "y": 0,
            "z": 3,
            "elements": [
                "immersiveengineering:sheetmetal@9"
            ]
        },
        {
            "x": 2,
            "y": 0,
            "z": 1,
            "elements": [
                "immersiveengineering:sheetmetal@9"
            ]
        },
        {
            "x": 2,
            "y": 0,
            "z": 3,
            "elements": [
                "immersiveengineering:sheetmetal@9"
            ]
        },
        {
            "x": 1,
            "y": 7,
            "z": 0,
            "elements": [
                "modularmachinery:blockcasing@1"
            ]
        },
        {
            "x": 2,
            "y": 7,
            "z": 0,
            "elements": [
                "modularmachinery:blockcasing@1"
            ]
        },
        {
            "x": 1,
            "y": 7,
            "z": 2,
            "elements": [
                "immersiveengineering:metal_device1@6"
            ]
        },
        {
            "x": 0,
            "y": 5,
            "z": 1,
            "elements": [
                "immersiveengineering:metal_decoration1_slab@1",
				"immersiveengineering:metal_decoration1_slab@2",
				"immersiveengineering:metal_decoration1_slab@3"
            ]
        },
        {
            "x": 1,
            "y": 5,
            "z": 1,
            "elements": [
                "immersiveengineering:sheetmetal@9"
            ]
        },
        {
            "x": 2,
            "y": 5,
            "z": 1,
            "elements": [
                "immersiveengineering:sheetmetal@9"
            ]
        },
        {
            "x": 1,
            "y": 3,
            "z": 0,
            "elements": [
                "immersiveengineering:sheetmetal@9"
            ]
        },
        {
            "x": 3,
            "y": 5,
            "z": 1,
            "elements": [
                "immersiveengineering:metal_decoration1_slab@1",
				"immersiveengineering:metal_decoration1_slab@2",
				"immersiveengineering:metal_decoration1_slab@3"
            ]
        },
        {
            "x": 2,
            "y": 3,
            "z": 0,
            "elements": [
                "immersiveengineering:sheetmetal@9"
            ]
        },
        {
            "x": 1,
            "y": 3,
            "z": 2,
            "elements": [
                "immersiveengineering:metal_device1@6"
            ]
        },
        {
            "x": 0,
            "y": 1,
            "z": 1,
            "elements": [
			    "immersiveengineering:metal_decoration1@1",
                "immersiveengineering:metal_decoration1@2",
				"immersiveengineering:metal_decoration1@3"
            ]
        },
        {
            "x": -1,
            "y": 1,
            "z": 3,
            "elements": [
                "immersiveengineering:sheetmetal@9"
            ]
        },
        {
            "x": 2,
            "y": 1,
            "z": 1,
            "elements": [
                "immersiveengineering:sheetmetal@9"
            ]
        },
        {
            "x": -1,
            "y": -1,
            "z": 2,
            "elements": [
			    "immersiveengineering:metal_decoration1@1",
                "immersiveengineering:metal_decoration1@2",
				"immersiveengineering:metal_decoration1@3"
            ]
        },
        {
            "x": 0,
            "y": -1,
            "z": 2,
            "elements": [
                "immersiveengineering:metal_decoration0@5"
            ]
        },
        {
            "x": 2,
            "y": 1,
            "z": 3,
            "elements": [
                "immersiveengineering:sheetmetal@9"
            ]
        },
        {
            "x": 1,
            "y": -1,
            "z": 2,
            "elements": [
                "immersiveengineering:metal_decoration0@5"
            ]
        },
        {
            "x": 2,
            "y": -1,
            "z": 2,
            "elements": [
			    "immersiveengineering:metal_decoration1@1",
                "immersiveengineering:metal_decoration1@2",
				"immersiveengineering:metal_decoration1@3"
            ]
        },
        {
            "x": 1,
            "y": 8,
            "z": 2,
            "elements": [
                "immersiveengineering:metal_device1@6"
            ]
        },
        {
            "x": 1,
            "y": 6,
            "z": 1,
            "elements": [
                "immersiveengineering:sheetmetal@9"
            ]
        },
        {
            "x": 2,
            "y": 6,
            "z": 1,
            "elements": [
                "immersiveengineering:sheetmetal@9"
            ]
        },
        {
            "x": 1,
            "y": 4,
            "z": 0,
            "elements": [
                "immersiveengineering:sheetmetal@9"
            ]
        },
        {
            "x": 2,
            "y": 4,
            "z": 0,
            "elements": [
                "immersiveengineering:sheetmetal@9"
            ]
        },
        {
            "x": 1,
            "y": 4,
            "z": 2,
            "elements": [
                "immersiveengineering:metal_device1@6"
            ]
        },
        {
            "x": 0,
            "y": 2,
            "z": 1,
            "elements": [
			    "immersiveengineering:metal_decoration1@1",
                "immersiveengineering:metal_decoration1@2",
				"immersiveengineering:metal_decoration1@3"
            ]
        }
    ]}